<robot name = "robot">
    <link name="Torso">
        <inertial>
            <origin xyz="1 0 3" rpy="0 0 0"/>
            <mass value="1" />
            <inertia ixx="100" ixy="0" ixz="0" iyy="100" iyz="0" izz="100" />
        </inertial>
        <visual>
            <origin xyz="1 0 3" rpy="0 0 0"/>
            <geometry>
                <box size="2 2 1.5" />
            </geometry>
            <material name="Cyan">
                <color rgba="0 1.0 1.0 1.0"/>
            </material>
        </visual>
        <collision>
            <origin xyz="1 0 3" rpy="0 0 0"/>
            <geometry>
                <box size="2 2 1.5" />
            </geometry>
        </collision>
    </link>
    <link name="Head">
        <inertial>
            <origin xyz="1 0 -0.25" rpy="0 0 0"/>
            <mass value="1" />
            <inertia ixx="100" ixy="0" ixz="0" iyy="100" iyz="0" izz="100" />
        </inertial>
        <visual>
            <origin xyz="1 0 -0.25" rpy="0 0 0"/>
            <geometry>
                <box size="1.5 1.5 1.5" />
            </geometry>
            <material name="Cyan">
                <color rgba="0 1.0 1.0 1.0"/>
            </material>
        </visual>
        <collision>
            <origin xyz="1 0 -0.25" rpy="0 0 0"/>
            <geometry>
                <box size="1.5 1.5 1.5" />
            </geometry>
        </collision>
    </link>
    <link name="Trunk">
        <inertial>
            <origin xyz="0.75 0 -2.75" rpy="0 0 0"/>
            <mass value="1" />
            <inertia ixx="100" ixy="0" ixz="0" iyy="100" iyz="0" izz="100" />
        </inertial>
        <visual>
            <origin xyz="0.75 0 -2.75" rpy="0 0 0"/>
            <geometry>
                <box size="0.5 0.5 2" />
            </geometry>
            <material name="Cyan">
                <color rgba="0 1.0 1.0 1.0"/>
            </material>
        </visual>
        <collision>
            <origin xyz="0.75 0 -2.75" rpy="0 0 0"/>
            <geometry>
                <box size="0.5 0.5 2" />
            </geometry>
        </collision>
    </link>
    <link name="Foot_1">
        <inertial>
            <origin xyz="0 0.5 -1.5" rpy="0 0 0"/>
            <mass value="1" />
            <inertia ixx="100" ixy="0" ixz="0" iyy="100" iyz="0" izz="100" />
        </inertial>
        <visual>
            <origin xyz="0 0.5 -1.5" rpy="0 0 0"/>
            <geometry>
                <box size="0.75 0.75 2" />
            </geometry>
            <material name="Cyan">
                <color rgba="0 1.0 1.0 1.0"/>
            </material>
        </visual>
        <collision>
            <origin xyz="0 0.5 -1.5" rpy="0 0 0"/>
            <geometry>
                <box size="0.75 0.75 2" />
            </geometry>
        </collision>
    </link>
    <joint name="Joint_1" type="revolute">
       <parent link="Torso"/>
       <child  link="Foot_1"/>
       <origin rpy="0 0 0" xyz="0 0.5 3.75" />
       <axis xyz="0 1 0"/>
       <limit effort="0.0" lower="-3.14159" upper="3.14159" velocity="0.0"/>
    </joint>
    <neuron name = "Touch_Sensor_1" type = "sensor" linkName = "Foot_1" />
    <link name="Foot_2">
        <inertial>
            <origin xyz="0 -0.5 -1.5" rpy="0 0 0"/>
            <mass value="1" />
            <inertia ixx="100" ixy="0" ixz="0" iyy="100" iyz="0" izz="100" />
        </inertial>
        <visual>
            <origin xyz="0 -0.5 -1.5" rpy="0 0 0"/>
            <geometry>
                <box size="0.75 0.75 2" />
            </geometry>
            <material name="Cyan">
                <color rgba="0 1.0 1.0 1.0"/>
            </material>
        </visual>
        <collision>
            <origin xyz="0 -0.5 -1.5" rpy="0 0 0"/>
            <geometry>
                <box size="0.75 0.75 2" />
            </geometry>
        </collision>
    </link>
    <joint name="Joint_2" type="revolute">
       <parent link="Torso"/>
       <child  link="Foot_2"/>
       <origin rpy="0 0 0" xyz="0 -0.5 3.75" />
       <axis xyz="0 1 0"/>
       <limit effort="0.0" lower="-3.14159" upper="3.14159" velocity="0.0"/>
    </joint>
    <neuron name = "Touch_Sensor_2" type = "sensor" linkName = "Foot_2" />
    <link name="Foot_3">
        <inertial>
            <origin xyz="1 0.5 -1.5" rpy="0 0 0"/>
            <mass value="1" />
            <inertia ixx="100" ixy="0" ixz="0" iyy="100" iyz="0" izz="100" />
        </inertial>
        <visual>
            <origin xyz="1 0.5 -1.5" rpy="0 0 0"/>
            <geometry>
                <box size="0.75 0.75 2" />
            </geometry>
            <material name="Cyan">
                <color rgba="0 1.0 1.0 1.0"/>
            </material>
        </visual>
        <collision>
            <origin xyz="1 0.5 -1.5" rpy="0 0 0"/>
            <geometry>
                <box size="0.75 0.75 2" />
            </geometry>
        </collision>
    </link>
    <joint name="Joint_3" type="revolute">
       <parent link="Torso"/>
       <child  link="Foot_3"/>
       <origin rpy="0 0 0" xyz="1 0.5 3.75" />
       <axis xyz="0 1 0"/>
       <limit effort="0.0" lower="-3.14159" upper="3.14159" velocity="0.0"/>
    </joint>
    <neuron name = "Touch_Sensor_3" type = "sensor" linkName = "Foot_3" />
    <link name="Foot_4">
        <inertial>
            <origin xyz="1 -0.5 -1.5" rpy="0 0 0"/>
            <mass value="1" />
            <inertia ixx="100" ixy="0" ixz="0" iyy="100" iyz="0" izz="100" />
        </inertial>
        <visual>
            <origin xyz="1 -0.5 -1.5" rpy="0 0 0"/>
            <geometry>
                <box size="0.75 0.75 2" />
            </geometry>
            <material name="Cyan">
                <color rgba="0 1.0 1.0 1.0"/>
            </material>
        </visual>
        <collision>
            <origin xyz="1 -0.5 -1.5" rpy="0 0 0"/>
            <geometry>
                <box size="0.75 0.75 2" />
            </geometry>
        </collision>
    </link>
    <joint name="Joint_4" type="revolute">
       <parent link="Torso"/>
       <child  link="Foot_4"/>
       <origin rpy="0 0 0" xyz="1 -0.5 3.75" />
       <axis xyz="0 1 0"/>
       <limit effort="0.0" lower="-3.14159" upper="3.14159" velocity="0.0"/>
    </joint>
    <neuron name = "Touch_Sensor_4" type = "sensor" linkName = "Foot_4" />
    <joint name="Head_Joint" type="revolute">
       <parent link="Torso"/>
       <child  link="Head"/>
       <origin rpy="0 0 0" xyz="1 0 4.5" />
       <axis xyz="0 1 0"/>
       <limit effort="0.0" lower="-3.14159" upper="3.14159" velocity="0.0"/>
    </joint>
    <joint name="Trunk_Joint" type="revolute">
       <parent link="Head"/>
       <child  link="Trunk"/>
       <origin rpy="0 0 0" xyz="1 0 1.5" />
       <axis xyz="0 1 0"/>
       <limit effort="0.0" lower="-3.14159" upper="3.14159" velocity="0.0"/>
    </joint>
</robot>